Workbook

Sheet 기대효과KPI
A1: 프로젝트 기대효과 KPI — Before(CASE1) vs After(CASE2)
A2: 값은 주문별·AMR별·충돌 시트에서 직접 계산하는 수식, 판정도 수식 (목표에 맞춰 조정하지 않은 실제 실행값)
A4: 기대효과 | B4: 계산식 | C4: Before (CASE1) | D4: After (CASE2) | E4: 개선율 | F4: 목표 | G4: 판정
A5: 작업 처리시간 단축 | B5: 출고완료 − 주문발생 (평균, 초) | C5: =AVERAGE(주문별_CASE1!$K$2:$K$1001) | D5: =AVERAGE(주문별_CASE2!$K$2:$K$1001) | E5: =IF(C5=0,"-",(C5-D5)/C5) | F5: 20~30% 단축 | G5: =IF(E5<0.2,"미달",IF(E5>0.3,"초과 달성","달성"))
A6: 설비 가동률 향상 | B6: 작업시간 / 전체시간 × 100 (실작업 가동률, 상대 개선율) | C6: =SUMIFS(AMR별!$F$2:$F$7,AMR별!$A$2:$A$7,"CASE1")/(COUNTIF(AMR별!$A$2:$A$7,"CASE1")*MAX(주문별_CASE1!$J$2:$J$1001))*100 | D6: =SUMIFS(AMR별!$F$2:$F$7,AMR별!$A$2:$A$7,"CASE2")/(COUNTIF(AMR별!$A$2:$A$7,"CASE2")*MAX(주문별_CASE2!$J$2:$J$1001))*100 | E6: =IF(C6=0,"-",(D6-C6)/C6) | F6: 15% 이상 향상 | G6: =IF(E6>=0.15,"달성","미달")
A7: 재고 정확도 확보 | B7: 일치 기록 / 전체 기록 × 100 | C7: =INDEX(시스템요약!$B$2:$B$89,MATCH("재고 정확도(%)",시스템요약!$A$2:$A$89,0)) | D7: =INDEX(시스템요약!$C$2:$C$89,MATCH("재고 정확도(%)",시스템요약!$A$2:$A$89,0)) | E7: =(D7-C7)/C7 | F7: 98% 이상 (방해요소 반영 후 평가) | G7: =IF(D7>=98,"달성","미달")
A8: 인력 의존도 감소 | B8: 충돌 해결 작업자 개입시간(초): (B − A) / B × 100 | C8: =SUM(충돌_CASE1!$G$2:$G$1016) | D8: =SUM(충돌_CASE2!$G$2:$G$2) | E8: =IF(C8=0,"-",(C8-D8)/C8) | F8: 10~15% 감소 | G8: =IF(E8<0.1,"미달",IF(E8>0.15,"초과 달성","달성"))
A9: └ 충돌 해결 개입 횟수 (보조) | B9: 충돌 1건 = 개입 1회 | C9: =COUNT(충돌_CASE1!$A$2:$A$1016) | D9: =COUNT(충돌_CASE2!$A$2:$A$2) | E9: =IF(C9=0,"-",(C9-D9)/C9) | F9: 보조지표 | G9: -
A10: 주문 대응시간 개선 | B10: 작업시작 − 주문발생 (평균, 초) | C10: =AVERAGE(주문별_CASE1!$L$2:$L$1001) | D10: =AVERAGE(주문별_CASE2!$L$2:$L$1001) | E10: =IF(C10=0,"-",(C10-D10)/C10) | F10: 25% 이상 개선 | G10: =IF(E10>=0.25,"달성","미달")
A12: · 개선율: 낮을수록 좋은 지표 (B−A)/B, 높을수록 좋은 지표 (A−B)/B. 양수 = After 가 좋음.
A13: · 설비 가동률: 실작업 가동률(빈 차 이동·대기 제외) 기준 상대 개선율. 기존 정의(이동+작업)는 시스템요약 참조.
A14: · 인력 의존도: AMR 충돌 1건마다 작업자가 현장에서 해결 (20~60초 랜덤, seed 고정, 해결 동안 AMR 정지). 주 지표 = 개입시간.
A15: · Before: 단순 순차 배정 + 독립 A* + 작업마다 작업장 복귀 / After: OR-Tools 후속 작업 선택 + 연속 수행 + Cooperative A*·예약테이블.

Sheet 결과정리
A1: AMR 창고 시뮬레이션 — 필요 데이터 결과 정리 (Before CASE1 vs After CASE2)
A2: CASE1: 단순 순차 배정 + 독립 A* + 작업마다 작업장 복귀 · CASE2: OR-Tools 후속 작업 선택(연속 수행) + Cooperative A* + 예약테이블 · AMR 3대, 주문 1,000건(입고·출고 작업 2,000건), seed 42 (두 CASE 동일 주문)
A4: 구분 | B4: 필요한 데이터 | C4: 단위 | D4: CASE1 (Before) | E4: CASE2 (After) | F4: 개선율 | G4: 출처 (시트 · 열) | H4: 비고
A5: 주문 | B5: 주문 발생시간 | C5: 초 | D5: =TEXT(MIN(주문별_CASE1!$C$2:$C$1001),"#,##0.0")&" ~ "&TEXT(MAX(주문별_CASE1!$C$2:$C$1001),"#,##0.0") | E5: =TEXT(MIN(주문별_CASE2!$C$2:$C$1001),"#,##0.0")&" ~ "&TEXT(MAX(주문별_CASE2!$C$2:$C$1001),"#,##0.0") | F5: - | G5: 주문별_CASE* · 발생시각(s) | H5: 첫 주문 ~ 마지막 주문 (주문별 값은 주문별 시트)
B6: 주문 완료시간 | C6: 초 | D6: =TEXT(MIN(주문별_CASE1!$J$2:$J$1001),"#,##0.0")&" ~ "&TEXT(MAX(주문별_CASE1!$J$2:$J$1001),"#,##0.0") | E6: =TEXT(MIN(주문별_CASE2!$J$2:$J$1001),"#,##0.0")&" ~ "&TEXT(MAX(주문별_CASE2!$J$2:$J$1001),"#,##0.0") | F6: - | G6: 주문별_CASE* · 출고완료(s) | H6: 첫 완료 ~ 마지막 완료
B7: └ 평균 총처리시간 (완료−발생) | C7: 초 | D7: =AVERAGE(주문별_CASE1!$K$2:$K$1001) | E7: =AVERAGE(주문별_CASE2!$K$2:$K$1001) | F7: =IF(D7=0,"-",(D7-E7)/D7) | G7: 주문별_CASE* · 총처리시간(s) | H7: 참고
B8: 주문 개수 | C8: 건 | D8: =COUNTA(주문별_CASE1!$A$2:$A$1001) | E8: =COUNTA(주문별_CASE2!$A$2:$A$1001) | F8: - | G8: 주문별_CASE* · 행 수
A9: AMR | B9: AMR별 이동거리 — AMR1 | C9: m | D9: =SUMIFS(AMR별!$D$2:$D$7,AMR별!$A$2:$A$7,"CASE1",AMR별!$B$2:$B$7,"AMR1") | E9: =SUMIFS(AMR별!$D$2:$D$7,AMR별!$A$2:$A$7,"CASE2",AMR별!$B$2:$B$7,"AMR1") | F9: =IF(D9=0,"-",(D9-E9)/D9) | G9: AMR별 · 이동거리(m)
B10: AMR별 이동거리 — AMR2 | C10: m | D10: =SUMIFS(AMR별!$D$2:$D$7,AMR별!$A$2:$A$7,"CASE1",AMR별!$B$2:$B$7,"AMR2") | E10: =SUMIFS(AMR별!$D$2:$D$7,AMR별!$A$2:$A$7,"CASE2",AMR별!$B$2:$B$7,"AMR2") | F10: =IF(D10=0,"-",(D10-E10)/D10) | G10: AMR별 · 이동거리(m)
B11: AMR별 이동거리 — AMR3 | C11: m | D11: =SUMIFS(AMR별!$D$2:$D$7,AMR별!$A$2:$A$7,"CASE1",AMR별!$B$2:$B$7,"AMR3") | E11: =SUMIFS(AMR별!$D$2:$D$7,AMR별!$A$2:$A$7,"CASE2",AMR별!$B$2:$B$7,"AMR3") | F11: =IF(D11=0,"-",(D11-E11)/D11) | G11: AMR별 · 이동거리(m)
B12: AMR별 이동거리 — 합계 | C12: m | D12: =SUMIFS(AMR별!$D$2:$D$7,AMR별!$A$2:$A$7,"CASE1") | E12: =SUMIFS(AMR별!$D$2:$D$7,AMR별!$A$2:$A$7,"CASE2") | F12: =IF(D12=0,"-",(D12-E12)/D12) | G12: AMR별 · 이동거리(m)
B13: AMR별 이동시간 — AMR1 | C13: sec | D13: =SUMIFS(AMR별!$E$2:$E$7,AMR별!$A$2:$A$7,"CASE1",AMR별!$B$2:$B$7,"AMR1") | E13: =SUMIFS(AMR별!$E$2:$E$7,AMR별!$A$2:$A$7,"CASE2",AMR별!$B$2:$B$7,"AMR1") | F13: =IF(D13=0,"-",(D13-E13)/D13) | G13: AMR별 · 이동시간(s)
B14: AMR별 이동시간 — AMR2 | C14: sec | D14: =SUMIFS(AMR별!$E$2:$E$7,AMR별!$A$2:$A$7,"CASE1",AMR별!$B$2:$B$7,"AMR2") | E14: =SUMIFS(AMR별!$E$2:$E$7,AMR별!$A$2:$A$7,"CASE2",AMR별!$B$2:$B$7,"AMR2") | F14: =IF(D14=0,"-",(D14-E14)/D14) | G14: AMR별 · 이동시간(s)
B15: AMR별 이동시간 — AMR3 | C15: sec | D15: =SUMIFS(AMR별!$E$2:$E$7,AMR별!$A$2:$A$7,"CASE1",AMR별!$B$2:$B$7,"AMR3") | E15: =SUMIFS(AMR별!$E$2:$E$7,AMR별!$A$2:$A$7,"CASE2",AMR별!$B$2:$B$7,"AMR3") | F15: =IF(D15=0,"-",(D15-E15)/D15) | G15: AMR별 · 이동시간(s)
B16: AMR별 이동시간 — 합계 | C16: sec | D16: =SUMIFS(AMR별!$E$2:$E$7,AMR별!$A$2:$A$7,"CASE1") | E16: =SUMIFS(AMR별!$E$2:$E$7,AMR별!$A$2:$A$7,"CASE2") | F16: =IF(D16=0,"-",(D16-E16)/D16) | G16: AMR별 · 이동시간(s)
B17: AMR별 작업시간 — AMR1 | C17: sec | D17: =SUMIFS(AMR별!$F$2:$F$7,AMR별!$A$2:$A$7,"CASE1",AMR별!$B$2:$B$7,"AMR1") | E17: =SUMIFS(AMR별!$F$2:$F$7,AMR별!$A$2:$A$7,"CASE2",AMR별!$B$2:$B$7,"AMR1") | F17: - | G17: AMR별 · 작업시간(s) | H17: 적재·RFID·적치·피킹·하역·WMS·작업자 개입 대기
B18: AMR별 작업시간 — AMR2 | C18: sec | D18: =SUMIFS(AMR별!$F$2:$F$7,AMR별!$A$2:$A$7,"CASE1",AMR별!$B$2:$B$7,"AMR2") | E18: =SUMIFS(AMR별!$F$2:$F$7,AMR별!$A$2:$A$7,"CASE2",AMR별!$B$2:$B$7,"AMR2") | F18: - | G18: AMR별 · 작업시간(s)
B19: AMR별 작업시간 — AMR3 | C19: sec | D19: =SUMIFS(AMR별!$F$2:$F$7,AMR별!$A$2:$A$7,"CASE1",AMR별!$B$2:$B$7,"AMR3") | E19: =SUMIFS(AMR별!$F$2:$F$7,AMR별!$A$2:$A$7,"CASE2",AMR별!$B$2:$B$7,"AMR3") | F19: - | G19: AMR별 · 작업시간(s)
B20: AMR별 작업시간 — 합계 | C20: sec | D20: =SUMIFS(AMR별!$F$2:$F$7,AMR별!$A$2:$A$7,"CASE1") | E20: =SUMIFS(AMR별!$F$2:$F$7,AMR별!$A$2:$A$7,"CASE2") | F20: - | G20: AMR별 · 작업시간(s)
B21: AMR별 대기시간 — AMR1 | C21: sec | D21: =SUMIFS(AMR별!$G$2:$G$7,AMR별!$A$2:$A$7,"CASE1",AMR별!$B$2:$B$7,"AMR1") | E21: =SUMIFS(AMR별!$G$2:$G$7,AMR별!$A$2:$A$7,"CASE2",AMR별!$B$2:$B$7,"AMR1") | F21: =IF(D21=0,"-",(D21-E21)/D21) | G21: AMR별 · 대기시간(s) | H21: 다른 AMR·병목 때문에 멈춘 시간 (재출발 지연 포함)
B22: AMR별 대기시간 — AMR2 | C22: sec | D22: =SUMIFS(AMR별!$G$2:$G$7,AMR별!$A$2:$A$7,"CASE1",AMR별!$B$2:$B$7,"AMR2") | E22: =SUMIFS(AMR별!$G$2:$G$7,AMR별!$A$2:$A$7,"CASE2",AMR별!$B$2:$B$7,"AMR2") | F22: =IF(D22=0,"-",(D22-E22)/D22) | G22: AMR별 · 대기시간(s)
B23: AMR별 대기시간 — AMR3 | C23: sec | D23: =SUMIFS(AMR별!$G$2:$G$7,AMR별!$A$2:$A$7,"CASE1",AMR별!$B$2:$B$7,"AMR3") | E23: =SUMIFS(AMR별!$G$2:$G$7,AMR별!$A$2:$A$7,"CASE2",AMR별!$B$2:$B$7,"AMR3") | F23: =IF(D23=0,"-",(D23-E23)/D23) | G23: AMR별 · 대기시간(s)
B24: AMR별 대기시간 — 합계 | C24: sec | D24: =SUMIFS(AMR별!$G$2:$G$7,AMR별!$A$2:$A$7,"CASE1") | E24: =SUMIFS(AMR별!$G$2:$G$7,AMR별!$A$2:$A$7,"CASE2") | F24: =IF(D24=0,"-",(D24-E24)/D24) | G24: AMR별 · 대기시간(s)
B25: AMR별 유휴시간 — AMR1 | C25: sec | D25: =SUMIFS(AMR별!$H$2:$H$7,AMR별!$A$2:$A$7,"CASE1",AMR별!$B$2:$B$7,"AMR1") | E25: =SUMIFS(AMR별!$H$2:$H$7,AMR별!$A$2:$A$7,"CASE2",AMR별!$B$2:$B$7,"AMR1") | F25: - | G25: AMR별 · 유휴시간(s) | H25: 배정된 주문 없이 서 있던 시간
B26: AMR별 유휴시간 — AMR2 | C26: sec | D26: =SUMIFS(AMR별!$H$2:$H$7,AMR별!$A$2:$A$7,"CASE1",AMR별!$B$2:$B$7,"AMR2") | E26: =SUMIFS(AMR별!$H$2:$H$7,AMR별!$A$2:$A$7,"CASE2",AMR별!$B$2:$B$7,"AMR2") | F26: - | G26: AMR별 · 유휴시간(s)
B27: AMR별 유휴시간 — AMR3 | C27: sec | D27: =SUMIFS(AMR별!$H$2:$H$7,AMR별!$A$2:$A$7,"CASE1",AMR별!$B$2:$B$7,"AMR3") | E27: =SUMIFS(AMR별!$H$2:$H$7,AMR별!$A$2:$A$7,"CASE2",AMR별!$B$2:$B$7,"AMR3") | F27: - | G27: AMR별 · 유휴시간(s)
B28: AMR별 유휴시간 — 합계 | C28: sec | D28: =SUMIFS(AMR별!$H$2:$H$7,AMR별!$A$2:$A$7,"CASE1") | E28: =SUMIFS(AMR별!$H$2:$H$7,AMR별!$A$2:$A$7,"CASE2") | F28: - | G28: AMR별 · 유휴시간(s)
A29: 충돌 | B29: 충돌 예상 횟수 | C29: 회 | D29: =INDEX(시스템요약!$B$2:$B$89,MATCH("경로 충돌 횟수",시스템요약!$A$2:$A$89,0))+INDEX(시스템요약!$B$2:$B$89,MATCH("정면 충돌 횟수",시스템요약!$A$2:$A$89,0)) | E29: =INDEX(시스템요약!$C$2:$C$89,MATCH("예약테이블 사전 회피(충돌 예상)",시스템요약!$A$2:$A$89,0)) | F29: - | G29: 시스템요약 | H29: CASE1 = 실제 발생한 경로충돌+정면충돌 / CASE2 = 예약테이블이 사전에 감지·회피한 수 (정의가 달라 개선율 미산출)
B30: 충돌 건수 (작업자 개입 기준) | C30: 회 | D30: =INDEX(시스템요약!$B$2:$B$89,MATCH("충돌 건수(경로+정면)",시스템요약!$A$2:$A$89,0)) | E30: =INDEX(시스템요약!$C$2:$C$89,MATCH("충돌 건수(경로+정면)",시스템요약!$A$2:$A$89,0)) | F30: =IF(D30=0,"-",(D30-E30)/D30) | G30: 시스템요약 · 충돌 건수(경로+정면) | H30: 작업자가 해결한 충돌 수 (해결 중·직후 같은 상황 반복은 1건)
B31: └ 실제 발생한 경로 충돌 | C31: 회 | D31: =INDEX(시스템요약!$B$2:$B$89,MATCH("경로 충돌 횟수",시스템요약!$A$2:$A$89,0)) | E31: =INDEX(시스템요약!$C$2:$C$89,MATCH("경로 충돌 횟수",시스템요약!$A$2:$A$89,0)) | F31: =IF(D31=0,"-",(D31-E31)/D31) | G31: 시스템요약 · 경로 충돌 횟수
B32: └ 실제 발생한 정면 충돌 | C32: 회 | D32: =INDEX(시스템요약!$B$2:$B$89,MATCH("정면 충돌 횟수",시스템요약!$A$2:$A$89,0)) | E32: =INDEX(시스템요약!$C$2:$C$89,MATCH("정면 충돌 횟수",시스템요약!$A$2:$A$89,0)) | F32: =IF(D32=0,"-",(D32-E32)/D32) | G32: 시스템요약 · 정면 충돌 횟수
B33: 충돌 회피를 위한 정지 횟수 | C33: 회 | D33: =INDEX(시스템요약!$B$2:$B$89,MATCH("정지 횟수",시스템요약!$A$2:$A$89,0)) | E33: =INDEX(시스템요약!$C$2:$C$89,MATCH("정지 횟수",시스템요약!$A$2:$A$89,0)) | F33: =IF(D33=0,"-",(D33-E33)/D33) | G33: 시스템요약 · 정지 횟수 | H33: 다른 AMR 때문에 멈춘 횟수 (예약 대기 포함)
A34: 병목 | B34: 병목구간 대기시간 | C34: sec | D34: =INDEX(시스템요약!$B$2:$B$89,MATCH("병목 대기시간(s)",시스템요약!$A$2:$A$89,0)) | E34: =INDEX(시스템요약!$C$2:$C$89,MATCH("병목 대기시간(s)",시스템요약!$A$2:$A$89,0)) | F34: =IF(D34=0,"-",(D34-E34)/D34) | G34: 시스템요약 · 병목 대기시간(s) | H34: 공용구역 밖에서 구역 진입을 기다린 시간 합계
B35: └ RFID | C35: sec | D35: =INDEX(시스템요약!$B$2:$B$89,MATCH("병목[RFID] 대기시간(s)",시스템요약!$A$2:$A$89,0)) | E35: =INDEX(시스템요약!$C$2:$C$89,MATCH("병목[RFID] 대기시간(s)",시스템요약!$A$2:$A$89,0)) | F35: =IF(D35=0,"-",(D35-E35)/D35) | G35: 시스템요약 · 병목[RFID] 대기시간(s)
B36: └ 중앙교차로 | C36: sec | D36: =INDEX(시스템요약!$B$2:$B$89,MATCH("병목[중앙교차로] 대기시간(s)",시스템요약!$A$2:$A$89,0)) | E36: =INDEX(시스템요약!$C$2:$C$89,MATCH("병목[중앙교차로] 대기시간(s)",시스템요약!$A$2:$A$89,0)) | F36: =IF(D36=0,"-",(D36-E36)/D36) | G36: 시스템요약 · 병목[중앙교차로] 대기시간(s)
B37: └ 좁은통로 | C37: sec | D37: =INDEX(시스템요약!$B$2:$B$89,MATCH("병목[좁은통로] 대기시간(s)",시스템요약!$A$2:$A$89,0)) | E37: =INDEX(시스템요약!$C$2:$C$89,MATCH("병목[좁은통로] 대기시간(s)",시스템요약!$A$2:$A$89,0)) | F37: =IF(D37=0,"-",(D37-E37)/D37) | G37: 시스템요약 · 병목[좁은통로] 대기시간(s)
B38: └ 출고진입부 | C38: sec | D38: =INDEX(시스템요약!$B$2:$B$89,MATCH("병목[출고진입부] 대기시간(s)",시스템요약!$A$2:$A$89,0)) | E38: =INDEX(시스템요약!$C$2:$C$89,MATCH("병목[출고진입부] 대기시간(s)",시스템요약!$A$2:$A$89,0)) | F38: =IF(D38=0,"-",(D38-E38)/D38) | G38: 시스템요약 · 병목[출고진입부] 대기시간(s)
B39: 병목구간 대기 AMR 수 (최대 동시) | C39: 대 | D39: =INDEX(시스템요약!$B$2:$B$89,MATCH("병목구간 최대 동시 대기 AMR 수",시스템요약!$A$2:$A$89,0)) | E39: =INDEX(시스템요약!$C$2:$C$89,MATCH("병목구간 최대 동시 대기 AMR 수",시스템요약!$A$2:$A$89,0)) | F39: =IF(D39=0,"-",(D39-E39)/D39) | G39: 시스템요약 · 병목구간 최대 동시 대기 AMR 수 | H39: 같은 순간 병목구간 앞에서 동시에 기다린 AMR 최대 대수
B40: └ RFID | C40: 대 | D40: =INDEX(시스템요약!$B$2:$B$89,MATCH("병목[RFID] 최대 동시 대기 AMR 수",시스템요약!$A$2:$A$89,0)) | E40: =INDEX(시스템요약!$C$2:$C$89,MATCH("병목[RFID] 최대 동시 대기 AMR 수",시스템요약!$A$2:$A$89,0)) | F40: =IF(D40=0,"-",(D40-E40)/D40) | G40: 시스템요약 · 병목[RFID] 최대 동시 대기 AMR 수
B41: └ 중앙교차로 | C41: 대 | D41: =INDEX(시스템요약!$B$2:$B$89,MATCH("병목[중앙교차로] 최대 동시 대기 AMR 수",시스템요약!$A$2:$A$89,0)) | E41: =INDEX(시스템요약!$C$2:$C$89,MATCH("병목[중앙교차로] 최대 동시 대기 AMR 수",시스템요약!$A$2:$A$89,0)) | F41: =IF(D41=0,"-",(D41-E41)/D41) | G41: 시스템요약 · 병목[중앙교차로] 최대 동시 대기 AMR 수
...

Sheet 시스템요약
A1: CASE | B1: CASE1 | C1: CASE2 | D1: ORTOOLS_ONLY | E1: COOP_ONLY
A2: 배정 | B2: 단순 순차 | C2: OR-Tools VRP | D2: OR-Tools VRP | E2: 단순 순차
A3: 경로 | B3: 독립 A* | C3: Cooperative A* + 예약테이블 | D3: 독립 A* | E3: Cooperative A* + 예약테이블
A4: 완료시간(makespan,s) | B4: 48812.6 | C4: 36999.4 | D4: 36660 | E4: 51471.9
A5: 시간당 처리량(건/h) | B5: 73.8 | C5: 97.3 | D5: 98.2 | E5: 69.9
A6: 평균 총처리시간(s) | B6: 17497.2 | C6: 11673.8 | D6: 11482.6 | E6: 18806.8
A7: 평균 주문 대응시간(s) | B7: 17380.3 | C7: 11336.2 | D7: 11170 | E7: 18693.8
A8: 평균 실행시간(s) | B8: 116.9 | C8: 337.6 | D8: 312.6 | E8: 113
A9: 최대 대기 주문 수 | B9: 711 | C9: 614 | D9: 610 | E9: 726
A10: 최대 대기 작업 수 | B10: 712 | C10: 621 | D10: 616 | E10: 726
A11: 작업 완료 후 정책 | B11: 작업장(입고장) 복귀 | C11: 후속 작업 연속 수행 | D11: 후속 작업 연속 수행 | E11: 작업장(입고장) 복귀
A12: 완료 작업 수(입고+출고) | B12: 2000 | C12: 2000 | D12: 2000 | E12: 2000
A13: 연속 수행 작업 수 | B13: 0 | C13: 1996 | D13: 1996 | E13: 0
A14: 연속 수행 비율(%) | B14: 0 | C14: 99.8 | D14: 99.8 | E14: 0
A15: 작업장 복귀 횟수 | B15: 1999 | C15: 0 | D15: 0 | E15: 1998
A16: 같은 AMR 가 입고→출고 연속 수행한 주문 수 | B16: 0 | C16: 760 | D16: 770 | E16: 0
A17: AMR별 작업 수 최대-최소 차 | B17: 7 | C17: 1 | D17: 1 | E17: 2
A18: 총 이동거리(m) | B18: 92987 | C18: 60929 | D18: 60865 | E18: 93060
A19: 총 이동시간(s) | B19: 95211.9 | C19: 61970.5 | D19: 62578.1 | E19: 92655.6
A20: 총 작업시간(s) | B20: 44192.2 | C20: 44192.2 | D20: 44192.2 | E20: 44192.2
A21: 총 대기시간(s) | B21: 6734.1 | C21: 4737.4 | D21: 3079.2 | E21: 17296.3
A22: 총 유휴시간(s) | B22: 299.9 | C22: 98.4 | D22: 130.8 | E22: 271.9
A23: 정지 횟수 | B23: 1680 | C23: 710 | D23: 636 | E23: 1532
... A85: 충돌 해결 작업자 개입시간(s) | B85: 40935.5 | C85: 30.9 | D85: 7493.9 | E85: 150.1
A86: 충돌 해결 개입 방식 | B86: 시간 기록만 (저장된 충돌 기록으로 사후 계산, AMR 정지 없음) | C86: 시간 기록만 (저장된 충돌 기록으로 사후 계산, AMR 정지 없음) | D86: 시간 기록만 (저장된 충돌 기록으로 사후 계산, AMR 정지 없음) | E86: 시간 기록만 (저장된 충돌 기록으로 사후 계산, AMR 정지 없음)
A87: 충돌 해결 대기로 AMR 정지한 시간(s) | B87: 0 | C87: 0 | D87: 0 | E87: 0
A88: 충돌 외 사람개입 합계(정체+배차, 참고) | B88: 437 | C88: 383 | D88: 237 | E88: 1016
A89: 작업자 투입시간[충돌 해결](s) | B89: 40935.5 | C89: 30.9 | D89: 7493.9 | E89: 150.1

Sheet AMR별
A1: CASE | B1: AMR | C1: 처리건수 | D1: 이동거리(m) | E1: 이동시간(s) | F1: 작업시간(s) | G1: 대기시간(s) | H1: 유휴시간(s) | I1: 태그대기(s) | J1: 고장(s) | K1: 정지 횟수 | L1: 가동률(%) | M1: 시간당 처리(건/h) | N1: 입고 작업 수 | O1: 출고 작업 수 | P1: 연속 수행 작업 수 | Q1: 작업장 복귀 횟수 | R1: 경로충돌 관여 | S1: 정면충돌 관여 | T1: 병목 횟수 | U1: 장시간정체 개입
A2: CASE1 | B2: AMR1 | C2: 329 | D2: 30996 | E2: 31725.3 | F2: 14650.1 | G2: 2343.3 | H2: 94 | I2: 0 | J2: 0 | K2: 582 | L2: 95 | M2: 24.3 | N2: 333 | O2: 329 | P2: 0 | Q2: 662 | R2: 372 | S2: 308 | T2: 119 | U2: 153
A3: CASE1 | B3: AMR2 | C3: 337 | D3: 31023 | E3: 31776.8 | F3: 14747.5 | G3: 2188.2 | H3: 100.2 | I3: 0 | J3: 0 | K3: 541 | L3: 95.3 | M3: 24.9 | N3: 332 | O3: 337 | P3: 0 | Q3: 668 | R3: 372 | S3: 306 | T3: 105 | U3: 136
A4: CASE1 | B4: AMR3 | C4: 334 | D4: 30968 | E4: 31709.8 | F4: 14794.6 | G4: 2202.6 | H4: 105.7 | I4: 0 | J4: 0 | K4: 557 | L4: 95.3 | M4: 24.6 | N4: 335 | O4: 334 | P4: 0 | Q4: 669 | R4: 370 | S4: 302 | T4: 104 | U4: 148
A5: CASE2 | B5: AMR1 | C5: 333 | D5: 20413 | E5: 20741.3 | F5: 14780.2 | G5: 1455.6 | H5: 22.4 | I5: 0 | J5: 0 | K5: 240 | L5: 96 | M5: 32.4 | N5: 334 | O5: 333 | P5: 666 | Q5: 0 | R5: 1 | S5: 0 | T5: 103 | U5: 118
A6: CASE2 | B6: AMR2 | C6: 332 | D6: 20286 | E6: 20632.2 | F6: 14585.4 | G6: 1767.1 | H6: 14.8 | I6: 0 | J6: 0 | K6: 260 | L6: 95.2 | M6: 32.3 | N6: 334 | O6: 332 | P6: 664 | Q6: 0 | R6: 0 | S6: 0 | T6: 120 | U6: 144
A7: CASE2 | B7: AMR3 | C7: 335 | D7: 20230 | E7: 20597 | F7: 14826.6 | G7: 1514.7 | H7: 61.2 | I7: 0 | J7: 0 | K7: 210 | L7: 95.7 | M7: 32.6 | N7: 332 | O7: 335 | P7: 666 | Q7: 0 | R7: 1 | S7: 0 | T7: 93 | U7: 119

Sheet 주문별_CASE1
A1: 주문ID | B1: 저장구역 | C1: 발생시각(s) | D1: 작업시작(배정)시각(s) | E1: 입고장 도착(s) | F1: RFID 통과(s) | G1: 저장구역 적치완료(s) | H1: 출고 작업 배정(s) | I1: 피킹 완료(s) | J1: 출고완료(s) | K1: 총처리시간(s) | L1: 주문 대응시간(s) | M1: 입고 배정 AMR | N1: 출고 배정 AMR | O1: 출고 연속 수행 | P1: 배정 당시 AMR-입고장 거리(m) | Q1: 배정 당시 AMR-피킹위치 거리(m) | R1: 입고 배차비용(s) | S1: 입고 최소 가능비용(s) | T1: 입고 최소비용 AMR | U1: 출고 배차비용(s) | V1: 출고 최소 가능비용(s) | W1: 출고 최소비용 AMR | X1: 배차 비효율 | Y1: 추가 이동거리(m) | Z1: 추가 예상시간(s) | AA1: 수동 배차 확인 개입 | AB1: 경로충돌 | AC1: 정면충돌 | AD1: 병목 횟수 | AE1: 병목 대기(s) | AF1: 장시간정체 개입 | AG1: 장시간정체 개입시간(s) | AH1: 이동거리(m) | AI1: 이동시간(s) | AJ1: 작업시간(s) | AK1: 대기시간(s) | AL1: 입고 토트 | AM1: 적치 슬롯 | AN1: 출고 토트 | AO1: 피킹 슬롯
A2: O0001 | B2: B | C2: 0 | D2: 0 | E2: 10.5 | F2: 21.8 | G2: 47 | H2: 63.2 | I2: 95.1 | J2: 132.9 | K2: 132.9 | L2: 0 | M2: AMR1 | N2: AMR1 | O2: 0 | P2: 15 | Q2: 15 | R2: 44.5 | S2: 43.8 | T2: AMR2 | U2: 57.6 | V2: 57.6 | W2: AMR1 | X2: 1 | Y2: 1 | Z2: 0.7 | AA2: 0 | AB2: 2 | AC2: 2 | AD2: 0 | AE2: 0 | AF2: 0 | AG2: 0 | AH2: 66 | AI2: 65.2 | AJ2: 44.3 | AK2: 7.2 | AL2: T-0151 | AM2: B-01-01 | AN2: T-0016 | AO2: B-01-05
A3: O0002 | B3: D | C3: 22.4 | D3: 22.4 | E3: 32.2 | F3: 42.7 | G3: 64.5 | H3: 82.6 | I3: 106.7 | J3: 149.4 | K3: 127 | L3: 0 | M3: AMR2 | N3: AMR2 | O3: 0 | P3: 14 | Q3: 13 | R3: 41.2 | S3: 41.2 | T3: AMR2 | U3: 53.1 | V3: 53.1 | W3: AMR2 | X3: 0 | Y3: 0 | Z3: 0 | AA3: 0 | AB3: 0 | AC3: 0 | AD3: 1 | AE3: 10.4 | AF3: 1 | AG3: 5.4 | AH3: 57 | AI3: 56.7 | AJ3: 41.8 | AK3: 10.4 | AL3: T-0152 | AM3: D-01-01 | AN3: T-0046 | AO3: D-04-03
A4: O0003 | B4: B | C4: 38.8 | D4: 38.8 | E4: 69.5 | F4: 82.5 | G4: 113.3 | H4: 129.5 | I4: 156.5 | J4: 188.6 | K4: 149.8 | L4: 0 | M4: AMR3 | N4: AMR3 | O4: 0 | P4: 31 | Q4: 15 | R4: 59.7 | S4: 57.3 | T4: AMR1 | U4: 58.8 | V4: 58.8 | W4: AMR3 | X4: 1 | Y4: 31 | Z4: 2.4 | AA4: 0 | AB4: 2 | AC4: 2 | AD4: 0 | AE4: 0 | AF4: 0 | AG4: 0 | AH4: 80 | AI4: 80.1 | AJ4: 45.5 | AK4: 8 | AL4: T-0153 | AM4: B-02-01 | AN4: T-0017 | AO4: B-05-03
A5: O0004 | B5: I | C5: 61.2 | D5: 156.6 | E5: 156.6 | F5: 170.1 | G5: 194.9 | H5: 209.7 | I5: 243.9 | J5: 272.6 | K5: 211.4 | L5: 95.4 | M5: AMR1 | N5: AMR1 | O5: 0 | P5: 0 | Q5: 15 | R5: 37.4 | S5: 37.4 | T5: AMR1 | U5: 54.5 | V5: 54.5 | W5: AMR1 | X5: 0 | Y5: 0 | Z5: 0 | AA5: 0 | AB5: 1 | AC5: 1 | AD5: 0 | AE5: 0 | AF5: 1 | AG5: 0.1 | AH5: 45 | AI5: 50 | AJ5: 46.1 | AK5: 5.1 | AL5: T-0154 | AM5: I-01-01 | AN5: T-0121 | AO5: I-04-03
A6: O0005 | B6: A | C6: 82.1 | D6: 173.1 | E6: 173.1 | F6: 185.8 | G6: 213.3 | H6: 219.7 | I6: 247.6 | J6: 289.7 | K6: 207.6 | L6: 91 | M6: AMR2 | N6: AMR3 | O6: 0 | P6: 0 | Q6: 21 | R6: 37.7 | S6: 37.7 | T6: AMR2 | U6: 64.9 | V6: 64.9 | W6: AMR3 | X6: 0 | Y6: 0 | Z6: 0 | AA6: 0 | AB6: 0 | AC6: 0 | AD6: 1 | AE6: 1.8 | AF6: 0 | AG6: 0 | AH6: 69 | AI6: 67.9 | AJ6: 40.5 | AK6: 1.8 | AL6: T-0155 | AM6: A-02-01 | AN6: T-0001 | AO6: A-02-03
A7: O0006 | B7: D | C7: 98.1 | D7: 234.9 | E7: 234.9 | F7: 250.6 | G7: 273.7 | H7: 287.8 | I7: 313.6 | J7: 343.8 | K7: 245.7 | L7: 136.8 | M7: AMR2 | N7: AMR2 | O7: 0 | P7: 0 | Q7: 13 | R7: 37.1 | S7: 37.1 | T7: AMR2 | U7: 51.5 | V7: 51.5 | W7: AMR2 | X7: 0 | Y7: 0 | Z7: 0 | AA7: 0 | AB7: 2 | AC7: 1 | AD7: 0 | AE7: 0 | AF7: 0 | AG7: 0 | AH7: 40 | AI7: 44.2 | AJ7: 45.9 | AK7: 4.7 | AL7: T-0156 | AM7: D-03-01 | AN7: T-0047 | AO7: D-01-02
A8: O0007 | B8: I | C8: 119.1 | D8: 300.3 | E8: 300.3 | F8: 314.8 | G8: 337.2 | H8: 352 | I8: 384.5 | J8: 413.5 | K8: 294.4 | L8: 181.2 | M8: AMR1 | N8: AMR1 | O8: 0 | P8: 0 | Q8: 15 | R8: 36 | S8: 36 | T8: AMR1 | U8: 54.7 | V8: 54.7 | W8: AMR1 | X8: 0 | Y8: 0 | Z8: 0 | AA8: 0 | AB8: 1 | AC8: 1 | AD8: 0 | AE8: 0 | AF8: 0 | AG8: 0 | AH8: 43 | AI8: 48.5 | AJ8: 44.9 | AK8: 5 | AL8: T-0157 | AM8: I-02-01 | AN8: T-0122 | AO8: I-03-02
A9: O0008 | B9: I | C9: 141.2 | D9: 316.7 | E9: 316.7 | F9: 330.3 | G9: 357.9 | H9: 372.5 | I9: 402.1 | J9: 431.5 | K9: 290.3 | L9: 175.5 | M9: AMR3 | N9: AMR2 | O9: 0 | P9: 0 | Q9: 15 | R9: 38.7 | S9: 38.7 | T9: AMR3 | U9: 52.4 | V9: 52.4 | W9: AMR2 | X9: 0 | Y9: 0 | Z9: 0 | AA9: 0 | AB9: 1 | AC9: 1 | AD9: 0 | AE9: 0 | AF9: 0 | AG9: 0 | AH9: 45 | AI9: 50.1 | AJ9: 45.3 | AK9: 4.8 | AL9: T-0158 | AM9: I-04-01 | AN9: T-0123 | AO9: I-03-01
A10: O0009 | B10: J | C10: 158.4 | D10: 382.2 | E10: 382.2 | F10: 396.1 | G10: 424.9 | H10: 437.2 | I10: 467 | J10: 501.5 | K10: 343.1 | L10: 223.8 | M10: AMR3 | N10: AMR1 | O10: 0 | P10: 0 | Q10: 21 | R10: 41.8 | S10: 41.8 | T10: AMR3 | U10: 61 | V10: 61 | W10: AMR1 | X10: 0 | Y10: 0 | Z10: 0 | AA10: 0 | AB10: 0 | AC10: 0 | AD10: 0 | AE10: 0 | AF10: 0 | AG10: 0 | AH10: 63 | AI10: 64.8 | AJ10: 42.2 | AK10: 0 | AL10: T-0159 | AM10: J-01-01 | AN10: T-0136 | AO10: J-04-02
A11: O0010 | B11: A | C11: 181.5 | D11: 445.1 | E11: 445.1 | F11: 456.2 | G11: 485.6 | H11: 508.3 | I11: 539.1 | J11: 577.8 | K11: 396.3 | L11: 263.6 | M11: AMR3 | N11: AMR3 | O11: 0 | P11: 0 | Q11: 21 | R11: 38.8 | S11: 38.8 | T11: AMR3 | U11: 69.2 | V11: 69.2 | W11: AMR3 | X11: 0 | Y11: 0 | Z11: 0 | AA11: 0 | AB11: 0 | AC11: 0 | AD11: 0 | AE11: 0 | AF11: 0 | AG11: 0 | AH11: 64 | AI11: 64.1 | AJ11: 45.9 | AK11: 0 | AL11: T-0160 | AM11: A-03-01 | AN11: T-0002 | AO11: A-05-03
A12: O0011 | B12: F | C12: 203.5 | D12: 456.3 | E12: 456.3 | F12: 472.5 | G12: 505.9 | H12: 525.2 | I12: 558.8 | J12: 590.5 | K12: 387 | L12: 252.8 | M12: AMR2 | N12: AMR1 | O12: 0 | P12: 0 | Q12: 23 | R12: 47.1 | S12: 47.1 | T12: AMR2 | U12: 60.6 | V12: 60.6 | W12: AMR1 | X12: 0 | Y12: 0 | Z12: 0 | AA12: 0 | AB12: 1 | AC12: 1 | AD12: 0 | AE12: 0 | AF12: 1 | AG12: 0.4 | AH12: 67 | AI12: 67 | AJ12: 42.5 | AK12: 5.4 | AL12: T-0161 | AM12: F-02-01 | AN12: T-0076 | AO12: F-05-05
A13: O0012 | B13: F | C13: 220.1 | D13: 535.9 | E13: 535.9 | F13: 547.2 | G13: 581 | H13: 601.5 | I13: 638.1 | J13: 673.8 | K13: 453.7 | L13: 315.8 | M13: AMR2 | N13: AMR3 | O13: 0 | P13: 0 | Q13: 23 | R13: 43.4 | S13: 43.4 | T13: AMR2 | U13: 63.2 | V13: 63.2 | W13: AMR3 | X13: 0 | Y13: 0 | Z13: 0 | AA13: 0 | AB13: 1 | AC13: 1 | AD13: 0 | AE13: 0 | AF13: 0 | AG13: 0 | AH13: 70 | AI13: 73 | AJ13: 41.4 | AK13: 3 | AL13: T-0162 | AM13: F-03-01 | AN13: T-0077 | AO13: F-01-01
... A1001: O1000 | B1001: I | C1001: 14003 | D1001: 48725.2 | E1001: 48725.2 | F1001: 48737.7 | G1001: 48759.6 | H1001: 48759.7 | I1001: 48789.4 | J1001: 48812.6 | K1001: 34809.6 | L1001: 34722.2 | M1001: AMR1 | N1001: AMR2 | O1001: 0 | P1001: 0 | Q1001: 19 | R1001: 33.5 | S1001: 33.5 | T1001: AMR1 | U1001: 52.1 | V1001: 52.1 | W1001: AMR2 | X1001: 0 | Y1001: 0 | Z1001: 0 | AA1001: 0 | AB1001: 0 | AC1001: 0 | AD1001: 0 | AE1001: 0 | AF1001: 0 | AG1001: 0 | AH1001: 47 | AI1001: 50.5 | AJ1001: 36.8 | AK1001: 0 | AL1001: T-1150 | AM1001: I-01-01 | AN1001: T-0946 | AO1001: I-02-01

Sheet 주문별_CASE2
A1: 주문ID | B1: 저장구역 | C1: 발생시각(s) | D1: 작업시작(배정)시각(s) | E1: 입고장 도착(s) | F1: RFID 통과(s) | G1: 저장구역 적치완료(s) | H1: 출고 작업 배정(s) | I1: 피킹 완료(s) | J1: 출고완료(s) | K1: 총처리시간(s) | L1: 주문 대응시간(s) | M1: 입고 배정 AMR | N1: 출고 배정 AMR | O1: 출고 연속 수행 | P1: 배정 당시 AMR-입고장 거리(m) | Q1: 배정 당시 AMR-피킹위치 거리(m) | R1: 입고 배차비용(s) | S1: 입고 최소 가능비용(s) | T1: 입고 최소비용 AMR | U1: 출고 배차비용(s) | V1: 출고 최소 가능비용(s) | W1: 출고 최소비용 AMR | X1: 배차 비효율 | Y1: 추가 이동거리(m) | Z1: 추가 예상시간(s) | AA1: 수동 배차 확인 개입 | AB1: 경로충돌 | AC1: 정면충돌 | AD1: 병목 횟수 | AE1: 병목 대기(s) | AF1: 장시간정체 개입 | AG1: 장시간정체 개입시간(s) | AH1: 이동거리(m) | AI1: 이동시간(s) | AJ1: 작업시간(s) | AK1: 대기시간(s) | AL1: 입고 토트 | AM1: 적치 슬롯 | AN1: 출고 토트 | AO1: 피킹 슬롯
A2: O0001 | B2: B | C2: 0 | D2: 0 | E2: 9.8 | F2: 21.1 | G2: 46.3 | H2: 46.4 | I2: 58.3 | J2: 91.4 | K2: 91.4 | L2: 0 | M2: AMR2 | N2: AMR2 | O2: 1 | P2: 14 | Q2: 1 | R2: 43.8 | S2: 43.8 | T2: AMR2 | U2: 44.6 | V2: 44.6 | W2: AMR2 | X2: 0 | Y2: 0 | Z2: 0 | AA2: 0 | AB2: 0 | AC2: 0 | AD2: 0 | AE2: 0 | AF2: 0 | AG2: 0 | AH2: 49 | AI2: 47 | AJ2: 44.3 | AK2: 0 | AL2: T-0151 | AM2: B-01-01 | AN2: T-0016 | AO2: B-01-05
A3: O0002 | B3: D | C3: 22.4 | D3: 22.4 | E3: 32.9 | F3: 43.4 | G3: 65.2 | H3: 65.3 | I3: 76.8 | J3: 110.6 | K3: 88.2 | L3: 0 | M3: AMR1 | N3: AMR1 | O3: 1 | P3: 15 | Q3: 1 | R3: 41.9 | S3: 41.9 | T3: AMR1 | U3: 41.5 | V3: 41.5 | W3: AMR1 | X3: 0 | Y3: 0 | Z3: 0 | AA3: 0 | AB3: 0 | AC3: 0 | AD3: 1 | AE3: 2 | AF3: 0 | AG3: 0 | AH3: 46 | AI3: 44.3 | AJ3: 41.8 | AK3: 2 | AL3: T-0152 | AM3: D-01-01 | AN3: T-0046 | AO3: D-04-03
A4: O0003 | B4: B | C4: 38.8 | D4: 61.2 | E4: 86.9 | F4: 99.9 | G4: 123.4 | H4: 123.5 | I4: 138.9 | J4: 169.6 | K4: 130.8 | L4: 22.4 | M4: AMR3 | N4: AMR3 | O4: 1 | P4: 31 | Q4: 1 | R4: 59.7 | S4: 50.3 | T4: AMR1 | U4: 45.8 | V4: 45.8 | W4: AMR3 | X4: 1 | Y4: 19 | Z4: 9.4 | AA4: 0 | AB4: 0 | AC4: 0 | AD4: 0 | AE4: 0 | AF4: 0 | AG4: 0 | AH4: 66 | AI4: 62.8 | AJ4: 45.5 | AK4: 0 | AL4: T-0153 | AM4: B-02-01 | AN4: T-0017 | AO4: B-05-03
A5: O0004 | B5: I | C5: 61.2 | D5: 110.7 | E5: 139.2 | F5: 152.7 | G5: 177.4 | H5: 202.5 | I5: 229.7 | J5: 257.9 | K5: 196.7 | L5: 49.5 | M5: AMR1 | N5: AMR2 | O5: 1 | P5: 25 | Q5: 14 | R5: 59.9 | S5: 59.9 | T5: AMR1 | U5: 52.6 | V5: 52.6 | W5: AMR2 | X5: 0 | Y5: 0 | Z5: 0 | AA5: 0 | AB5: 0 | AC5: 0 | AD5: 0 | AE5: 0 | AF5: 0 | AG5: 0 | AH5: 69 | AI5: 71 | AJ5: 46.1 | AK5: 5 | AL5: T-0155 | AM5: I-01-01 | AN5: T-0121 | AO5: I-04-03
A6: O0005 | B6: A | C6: 82.1 | D6: 96.5 | E6: 115 | F6: 127.7 | G6: 155.2 | H6: 155.3 | I6: 163.6 | J6: 202.4 | K6: 120.3 | L6: 14.4 | M6: AMR2 | N6: AMR2 | O6: 1 | P6: 20 | Q6: 1 | R6: 55.7 | S6: 55.7 | T6: AMR2 | U6: 47.7 | V6: 47.7 | W6: AMR2 | X6: 0 | Y6: 0 | Z6: 0 | AA6: 0 | AB6: 0 | AC6: 0 | AD6: 0 | AE6: 0 | AF6: 0 | AG6: 0 | AH6: 68 | AI6: 65.3 | AJ6: 40.5 | AK6: 0 | AL6: T-0154 | AM6: A-02-01 | AN6: T-0001 | AO6: A-02-03
A7: O0006 | B7: D | C7: 98.1 | D7: 177.5 | E7: 207.5 | F7: 223.2 | G7: 246.3 | H7: 246.4 | I7: 256.6 | J7: 298.1 | K7: 200 | L7: 79.4 | M7: AMR1 | N7: AMR1 | O7: 1 | P7: 14 | Q7: 0 | R7: 51.3 | S7: 51.3 | T7: AMR1 | U7: 39.2 | V7: 39.2 | W7: AMR1 | X7: 0 | Y7: 0 | Z7: 0 | AA7: 0 | AB7: 0 | AC7: 0 | AD7: 1 | AE7: 12.2 | AF7: 2 | AG7: 18.2 | AH7: 43 | AI7: 46.4 | AJ7: 45.9 | AK7: 28.2 | AL7: T-0157 | AM7: D-03-01 | AN7: T-0047 | AO7: D-01-02
A8: O0007 | B8: I | C8: 119.1 | D8: 258 | E8: 281.5 | F8: 296 | G8: 318.3 | H8: 318.4 | I8: 331.7 | J8: 360.2 | K8: 241.1 | L8: 138.9 | M8: AMR2 | N8: AMR2 | O8: 1 | P8: 25 | Q8: 1 | R8: 58.5 | S8: 58.5 | T8: AMR2 | U8: 40.5 | V8: 40.5 | W8: AMR2 | X8: 0 | Y8: 0 | Z8: 0 | AA8: 0 | AB8: 0 | AC8: 0 | AD8: 0 | AE8: 0 | AF8: 0 | AG8: 0 | AH8: 54 | AI8: 57.2 | AJ8: 44.9 | AK8: 0 | AL8: T-0158 | AM8: I-02-01 | AN8: T-0122 | AO8: I-03-02
A9: O0008 | B9: I | C9: 141.2 | D9: 371.2 | E9: 398.8 | F9: 412.4 | G9: 439.9 | H9: 440 | I9: 450.6 | J9: 481.6 | K9: 340.4 | L9: 230 | M9: AMR1 | N9: AMR1 | O9: 1 | P9: 14 | Q9: 1 | R9: 52.3 | S9: 52.3 | T9: AMR1 | U9: 38.2 | V9: 38.2 | W9: AMR1 | X9: 0 | Y9: 0 | Z9: 0 | AA9: 0 | AB9: 0 | AC9: 0 | AD9: 1 | AE9: 3 | AF9: 1 | AG9: 8 | AH9: 45 | AI9: 49 | AJ9: 45.3 | AK9: 16 | AL9: T-0162 | AM9: I-04-01 | AN9: T-0123 | AO9: I-03-01
A10: O0009 | B10: J | C10: 158.4 | D10: 169.7 | E10: 193.2 | F10: 207.1 | G10: 235.8 | H10: 235.9 | I10: 247.3 | J10: 280.3 | K10: 121.9 | L10: 11.3 | M10: AMR3 | N10: AMR3 | O10: 1 | P10: 25 | Q10: 1 | R10: 64.3 | S10: 63.8 | T10: AMR1 | U10: 42.6 | V10: 42.6 | W10: AMR3 | X10: 1 | Y10: 11 | Z10: 0.5 | AA10: 0 | AB10: 0 | AC10: 0 | AD10: 0 | AE10: 0 | AF10: 0 | AG10: 0 | AH10: 68 | AI10: 68.3 | AJ10: 42.2 | AK10: 0 | AL10: T-0156 | AM10: J-01-01 | AN10: T-0136 | AO10: J-04-02
A11: O0010 | B11: A | C11: 181.5 | D11: 280.4 | E11: 305.9 | F11: 317 | G11: 346.4 | H11: 346.5 | I11: 360.8 | J11: 397.1 | K11: 215.6 | L11: 98.9 | M11: AMR3 | N11: AMR3 | O11: 1 | P11: 25 | Q11: 0 | R11: 61.3 | S11: 61.3 | T11: AMR3 | U11: 51.3 | V11: 51.3 | W11: AMR3 | X11: 0 | Y11: 0 | Z11: 0 | AA11: 0 | AB11: 0 | AC11: 0 | AD11: 0 | AE11: 0 | AF11: 0 | AG11: 0 | AH11: 70 | AI11: 68.7 | AJ11: 45.9 | AK11: 2 | AL11: T-0159 | AM11: A-03-01 | AN11: T-0002 | AO11: A-05-03
A12: O0011 | B12: F | C12: 203.5 | D12: 481.7 | E12: 509.2 | F12: 525.4 | G12: 557.9 | H12: 558 | I12: 568.1 | J12: 599.9 | K12: 396.4 | L12: 278.2 | M12: AMR1 | N12: AMR1 | O12: 1 | P12: 25 | Q12: 0 | R12: 69.6 | S12: 69.6 | T12: AMR1 | U12: 40.1 | V12: 40.1 | W12: AMR1 | X12: 0 | Y12: 0 | Z12: 0 | AA12: 0 | AB12: 0 | AC12: 0 | AD12: 0 | AE12: 0 | AF12: 0 | AG12: 0 | AH12: 72 | AI12: 71.6 | AJ12: 42.5 | AK12: 4 | AL12: T-0165 | AM12: F-03-01 | AN12: T-0077 | AO12: F-01-01
A13: O0012 | B13: F | C13: 220.1 | D13: 397.2 | E13: 422.7 | F13: 434 | G13: 468.5 | H13: 468.6 | I13: 479.6 | J13: 511.3 | K13: 291.2 | L13: 177.1 | M13: AMR3 | N13: AMR3 | O13: 1 | P13: 25 | Q13: 1 | R13: 65.9 | S13: 65.9 | T13: AMR3 | U13: 43.4 | V13: 43.4 | W13: AMR3 | X13: 0 | Y13: 0 | Z13: 0 | AA13: 0 | AB13: 0 | AC13: 0 | AD13: 0 | AE13: 0 | AF13: 0 | AG13: 0 | AH13: 72 | AI13: 70.6 | AJ13: 41.4 | AK13: 2 | AL13: T-0163 | AM13: F-02-01 | AN13: T-0076 | AO13: F-05-05
... A1001: O1000 | B1001: I | C1001: 14003 | D1001: 36626.3 | E1001: 36649.8 | F1001: 36662.3 | G1001: 36684.1 | H1001: 36684.2 | I1001: 36694.3 | J1001: 36730.4 | K1001: 22727.4 | L1001: 22623.3 | M1001: AMR3 | N1001: AMR3 | O1001: 1 | P1001: 25 | Q1001: 1 | R1001: 56 | S1001: 49.8 | T1001: AMR1 | U1001: 34.9 | V1001: 34.9 | W1001: AMR3 | X1001: 1 | Y1001: 11 | Z1001: 6.2 | AA1001: 0 | AB1001: 0 | AC1001: 0 | AD1001: 1 | AE1001: 13 | AF1001: 1 | AG1001: 8 | AH1001: 52 | AI1001: 54.2 | AJ1001: 36.8 | AK1001: 13 | AL1001: T-1147 | AM1001: I-02-01 | AN1001: T-0945 | AO1001: I-01-03

Sheet 충돌_CASE1
A1: collision_id | B1: time | C1: amr_1 | D1: amr_2 | E1: collision_type | F1: location | G1: human_intervention_time | H1: orders
A2: 1 | B2: 63.2 | C2: AMR1 | D2: AMR3 | E2: 경로충돌 | F2: (14, 19) | G2: 30.9 | H2: O0001 O0003
A3: 2 | B3: 63.8 | C3: AMR1 | D3: AMR3 | E3: 정면충돌 | F3: (14, 19)<->(15, 19) | G3: 39.5 | H3: O0001 O0003
A4: 3 | B4: 95.4 | C4: AMR1 | D4: AMR3 | E4: 경로충돌 | F4: (8, 11) | G4: 23.3 | H4: O0001 O0003
A5: 4 | B5: 96.9 | C5: AMR1 | D5: AMR3 | E5: 정면충돌 | F5: (8, 11)<->(9, 11) | G5: 33.5 | H5: O0001 O0003
A6: 5 | B6: 210.8 | C6: AMR1 | D6: AMR3 | E6: 경로충돌 | F6: (16, 19) | G6: 22.9 | H6: O0004
A7: 6 | B7: 211.4 | C7: AMR1 | D7: AMR3 | E7: 정면충돌 | F7: (16, 19)<->(17, 19) | G7: 20.4 | H7: O0004
A8: 7 | B8: 291.7 | C8: AMR1 | D8: AMR2 | E8: 경로충돌 | F8: (18, 18) | G8: 31.4 | H8: O0006
A9: 8 | B9: 292.6 | C9: AMR1 | D9: AMR2 | E9: 정면충돌 | F9: (18, 17)<->(18, 18) | G9: 24.7 | H9: O0006
A10: 9 | B10: 302.7 | C10: AMR2 | D10: AMR3 | E10: 경로충돌 | F10: (18, 11) | G10: 32.4 | H10: O0006
A11: 10 | B11: 359.5 | C11: AMR1 | D11: AMR2 | E11: 경로충돌 | F11: (18, 14) | G11: 49.7 | H11: O0007
A12: 11 | B12: 360.2 | C12: AMR1 | D12: AMR2 | E12: 정면충돌 | F12: (18, 13)<->(18, 14) | G12: 21.4 | H12: O0007
A13: 12 | B13: 373.3 | C13: AMR2 | D13: AMR3 | E13: 경로충돌 | F13: (16, 19) | G13: 45 | H13: O0008
... A33: 32 | B33: 1593.9 | C33: AMR2 | D33: AMR3 | E33: 정면충돌 | F33: (16, 19)<->(17, 19) | G33: 55.1 | H33: O0032
A34: 33 | B34: 1835.8 | C34: AMR2 | D34: AMR3 | E34: 경로충돌 | F34: (15, 19) | G34: 49.8
A35: 34 | B35: 1958 | C35: AMR1 | D35: AMR3 | E35: 경로충돌 | F35: (15, 19) | G35: 46.4
A36: 35 | B36: 1958.4 | C36: AMR1 | D36: AMR3 | E36: 정면충돌 | F36: (15, 19)<->(16, 19) | G36: 54.7 | H36: O0040
A37: 36 | B37: 2027.1 | C37: AMR1 | D37: AMR3 | E37: 경로충돌 | F37: (18, 11) | G37: 49.3 | H37: O0041
A38: 37 | B38: 2027.5 | C38: AMR1 | D38: AMR3 | E38: 정면충돌 | F38: (18, 11)<->(18, 12) | G38: 52.4 | H38: O0041
A39: 38 | B39: 2103.7 | C39: AMR1 | D39: AMR3 | E39: 경로충돌 | F39: (17, 19) | G39: 45.7 | H39: O0043
A40: 39 | B40: 2104.1 | C40: AMR1 | D40: AMR3 | E40: 정면충돌 | F40: (16, 19)<->(17, 19) | G40: 43.7 | H40: O0043
A41: 40 | B41: 2139.2 | C41: AMR1 | D41: AMR3 | E41: 경로충돌 | F41: (25, 11) | G41: 22.4 | H41: O0043 O0044
A42: 41 | B42: 2139.5 | C42: AMR1 | D42: AMR3 | E42: 정면충돌 | F42: (24, 11)<->(25, 11) | G42: 56.4 | H42: O0043 O0044
A43: 42 | B43: 2317.9 | C43: AMR1 | D43: AMR3 | E43: 경로충돌 | F43: (18, 11) | G43: 56.5
A44: 43 | B44: 2329.4 | C44: AMR2 | D44: AMR3 | E44: 정면충돌 | F44: (16, 19)<->(17, 19) | G44: 34.1 | H44: O0047
A45: 44 | B45: 2337.9 | C45: AMR1 | D45: AMR3 | E45: 경로충돌 | F45: (16, 19) | G45: 45.1 | H45: O0048
A46: 45 | B46: 2338.1 | C46: AMR1 | D46: AMR3 | E46: 정면충돌 | F46: (16, 19)<->(17, 19) | G46: 20.7 | H46: O0048
A47: 46 | B47: 2455.9 | C47: AMR1 | D47: AMR3 | E47: 경로충돌 | F47: (18, 9) | G47: 40
A48: 47 | B48: 2459.5 | C48: AMR2 | D48: AMR3 | E48: 경로충돌 | F48: (17, 10) | G48: 44.9 | H48: O0051
A49: 48 | B49: 2460.3 | C49: AMR2 | D49: AMR3 | E49: 정면충돌 | F49: (17, 10)<->(17, 11) | G49: 31.8 | H49: O0051
A50: 49 | B50: 2473.7 | C50: AMR1 | D50: AMR3 | E50: 경로충돌 | F50: (16, 19) | G50: 36.6 | H50: O0050
A51: 50 | B51: 2474.6 | C51: AMR1 | D51: AMR3 | E51: 정면충돌 | F51: (16, 19)<->(17, 19) | G51: 53.4 | H51: O0050
A52: 51 | B52: 2486.7 | C52: AMR2 | D52: AMR3 | E52: 경로충돌 | F52: (17, 17) | G52: 25.7 | H52: O0051
A53: 52 | B53: 2487 | C53: AMR2 | D53: AMR3 | E53: 정면충돌 | F53: (17, 17)<->(17, 18) | G53: 38.2 | H53: O0051
A54: 53 | B54: 2561.4 | C54: AMR1 | D54: AMR2 | E54: 경로충돌 | F54: (13, 19) | G54: 23.5 | H54: O0052
A55: 54 | B55: 2562 | C55: AMR1 | D55: AMR2 | E55: 정면충돌 | F55: (12, 19)<->(13, 19) | G55: 35.4 | H55: O0052
A56: 55 | B56: 2643.5 | C56: AMR1 | D56: AMR2 | E56: 경로충돌 | F56: (18, 11) | G56: 55.3 | H56: O0053
A57: 56 | B57: 2713.6 | C57: AMR1 | D57: AMR3 | E57: 경로충돌 | F57: (15, 19) | G57: 44.5
A58: 57 | B58: 2714.2 | C58: AMR1 | D58: AMR3 | E58: 정면충돌 | F58: (14, 19)<->(15, 19) | G58: 21.2 | H58: O0055
A59: 58 | B59: 2787.9 | C59: AMR1 | D59: AMR3 | E59: 경로충돌 | F59: (18, 10) | G59: 54.3 | H59: O0057
...

Sheet 충돌_CASE2
A1: collision_id | B1: time | C1: amr_1 | D1: amr_2 | E1: collision_type | F1: location | G1: human_intervention_time | H1: orders
A2: 1 | B2: 12597.9 | C2: AMR1 | D2: AMR3 | E2: 경로충돌 | F2: (15, 19) | G2: 30.9 | H2: O0344 O0347
